Workbook
Name BoxPlot: "BoxPlot"
Name Bubble: "Bubble"
Name Candlestick: "Candlestick"
Name Chart: "Chart"
Name ChartImage: "ChartImage"
Name ColumnRange: "ColumnRange"
Name Dumbbell: "Dumbbell"
Name Heatmap: "Heatmap"
Name Histogram: "Histogram"
Name Map: "Map"
Name OHLC: "OHLC"
Name PieChart: "PieChart"
Name Scatter: "Scatter"
Name Series: "Series"
Name Stripe: "Stripe"
Name Table: "Table"
Name TM1REBUILDOPTION: 1
Name TreeMap: "TreeMap"
Name Type: #REF!
Name Type: #REF!
Name Waterfall: "Waterfall"

Sheet ss
D1: Full | E1: Recent | F1: Calibrated | J1: Full | K1: Recent | L1: Calibrated
B2: omegacv | D2: =AVERAGE('SA data'!B42:B137)/AVERAGE('SA data'!$A$42:$A$137) -> 0.53627456 | E2: =AVERAGE('SA data'!B78:B137)/AVERAGE('SA data'!$A$78:$A$137) -> 0.56480372 | F2: 0.6 | I2: z | J2: =D7*D51^((1-D56)/D56)*D54 -> 2.8991526 | K2: =E7*E51^((1-E56)/E56)*E54 -> 2.9408688 | L2: =F7*F51^((1-F56)/F56)*F54 -> 2.7870006 | O2: 2.38
B3: omegaiv | D3: =1-D2-D4-D13-D5+D6 -> 0.18913384 | E3: =1-E2-E4-E13-E5+E6 -> 0.19403025 | F3: =1-F2-F4-F13-F5+F6 -> 0.18 | I3: v | J3: =J2/D7 -> 1.7612183 | K3: =K2/E7 -> 1.8016794 | L3: =L2/F7 -> 1.6890913 | O3: =8*9-6 -> 66
B4: omegagv | D4: =AVERAGE('SA data'!C42:C137)/AVERAGE('SA data'!$A$42:$A$137) -> 0.12620883 | E4: =AVERAGE('SA data'!C78:C137)/AVERAGE('SA data'!$A$78:$A$137) -> 0.12970996 | F4: 0.13 | I4: c | J4: =D2*J3 -> 0.94449656 | K4: =E2*K3 -> 1.0175952 | L4: =F2*L3 -> 1.0134548 | O4: =O2/((O3)^(1/2)) -> 0.29295775 | R4: # omegacgv = 0.10; //fed gov consumption
B5: omegaxv | D5: =AVERAGE('SA data'!E42:E137)/AVERAGE('SA data'!$A$42:$A$137) -> 0.74877771 | E5: =AVERAGE('SA data'!E78:E137)/AVERAGE('SA data'!$A$78:$A$137) -> 0.70384792 | F5: 0.7 | I5: i | J5: =D3*J3 -> 0.33310598 | K5: =ss!E3*K3 -> 0.34958031 | L5: =F3*L3 -> 0.30403643 | R5: # omegatrv = 0.045; // government transfers
B6: omegamv | D6: =AVERAGE('SA data'!F42:F137)/AVERAGE('SA data'!$A$42:$A$137) -> 0.64610633 | E6: =AVERAGE('SA data'!F78:F137)/AVERAGE('SA data'!$A$78:$A$137) -> 0.63229309 | F6: 0.65 | I6: io | J6: =D13*J3 -> 0.080507722 | K6: =E13*K3 -> 0.071889256 | L6: =F13*L3 -> 0.067563651 | R6: # omegabv = 2.5; // government debt-to-GDP ratio
B7: omegazv | D7: =D2+D3+D13+D4+D5 -> 1.6461063 | E7: =E2+E3+E13+E4+E5 -> 1.6322931 | F7: =F2+F3+F13+F4+F5 -> 1.65 | I7: g | J7: =D4*J3 -> 0.2222813 | K7: =E4*K3 -> 0.23369576 | L7: =F4*L3 -> 0.21958187 | O7: =13333*5 -> 66665 | R7: # omegarev = omegacgv + omegaigv + omegatrv + (r - 1)*omegabv; // required steady-state revenue
B8: omegavz | D8: =1/D7 -> 0.60749417 | E8: =1/E7 -> 0.61263507 | F8: =1/F7 -> 0.60606061 | I8: x | J8: =D5*J3 -> 1.318761 | K8: =E5*K3 -> 1.2681083 | L8: =F5*L3 -> 1.1823639 | R8: # omegatxv = 0.75 * omegarev; // tax revenue
I9: m | J9: =D6*J3 -> 1.1379343 | K9: =E6*K3 -> 1.1391894 | L9: =F6*L3 -> 1.0979093 | R9: # omegatxh = (1/3) * omegatxv;
I10: k | J10: =D51*J3 -> 11.103533 | K10: =E51*K3 -> 11.652677 | L10: =F51*L3 -> 10.134548 | R10: # omegatxf = (2/3) * omegatxv;
I11: w | J11: =D55*J3 -> 1.1741455 | K11: =E55*K3 -> 1.2011196 | L11: =F55*L3 -> 1.1260609 | R11: # omegantxv = 0.25 * omegarev; // non-tax revenue
B12: omegacgv | D12: =AVERAGE('SA data'!I42:I137)/AVERAGE('SA data'!$A$42:$A$137) -> 0.11441127 | E12: =AVERAGE('SA data'!I78:I137)/AVERAGE('SA data'!$A$78:$A$137) -> 0.1116033 | F12: 0.1 | I12: rev | J12: =D26*J3 -> 0.38708261 | K12: =E26*K3 -> 0.3908848 | L12: =F26*L3 -> 0.34626371
B13: omegaigv | D13: =AVERAGE('SA data'!J42:J137)/AVERAGE('SA data'!$A$42:$A$137) -> 0.045711382 | E13: =AVERAGE('SA data'!J78:J137)/AVERAGE('SA data'!$A$78:$A$137) -> 0.039901248 | F13: 0.04 | I13: tx | J13: =D27*J3 -> 0.29031196 | K13: =E27*K3 -> 0.2931636 | L13: =F27*L3 -> 0.25969779
B14: omegatrv | D14: =AVERAGE('SA data'!K2:K137)/AVERAGE('SA data'!$A$2:$A$137) -> 0.037304253 | E14: =AVERAGE('SA data'!K78:K137)/AVERAGE('SA data'!$A$78:$A$137) -> 0.0439511 | F14: 0.045 | I14: txh | J14: =D29*J3 -> 0.096770652 | K14: =E29*K3 -> 0.097721201 | L14: =F29*L3 -> 0.086565928
B15: omegaintv | D15: =AVERAGE('SA data'!L2:L137)/AVERAGE('SA data'!$A$2:$A$137) -> 0.022354266 | E15: =AVERAGE('SA data'!L78:L137)/AVERAGE('SA data'!$A$78:$A$137) -> 0.021500157 | F15: 0.02 | I15: txf | J15: =D30*J3 -> 0.1935413 | K15: =E30*K3 -> 0.1954424 | L15: =F30*L3 -> 0.17313186
B16: omegabv | D16: =D15/(D49-1) -> 2.5483863 | E16: =E15/(E49-1) -> 2.4510179 | F16: =F15/(F49-1) -> 2.66 | G16: =F16/4 -> 0.665 | I16: ntx | J16: =D28*J3 -> 0.096770652 | K16: =E28*K3 -> 0.097721201 | L16: =F28*L3 -> 0.086565928 | Q16: =T16/$U$19 -> #DIV/0! | R16: omegacgv | T16: ='SA data'!I167 -> 0
B17: omegarevv | D17: =D18+D21 -> 0.18366004 | E17: =E18+E21 -> 0.17335321 | F17: =F12+F13+F14+F15 -> 0.205 | I17: tr | J17: =D14*J3 -> 0.065700932 | K17: =E14*K3 -> 0.079185791 | L17: =F14*L3 -> 0.076009108 | Q17: =T17/$U$19 -> #DIV/0! | R17: omegaigv | T17: ='SA data'!J167 -> 0
B18: omegatxv | D18: =D19+D20 -> 0.13565498 | E18: =E19+E20 -> 0.12685146 | F18: =0.75*F17 -> 0.15375 | I18: b | J18: =ss!D16*J3 -> 4.4882645 | K18: =ss!E16*K3 -> 4.4159485 | L18: =F16*L3 -> 4.4929828 | Q18: =T18/$U$19 -> #DIV/0! | R18: omegatrv | T18: ='SA data'!K167 -> 0
B19: omegatxhv | D19: =AVERAGE('SA data'!O2:O137)/AVERAGE('SA data'!$A$2:$A$137) -> 0.040917784 | E19: =AVERAGE('SA data'!O78:O137)/AVERAGE('SA data'!$A$78:$A$137) -> 0.041105824 | F19: =(1/3)*F18 -> 0.05125 | I19: cr | K19: =E32*K3 -> 8.0374015 | L19: =F32*L3 -> 7.5164562 | Q19: =T19/$U$19 -> #DIV/0! | R19: omegaintv | T19: ='SA data'!L167 -> 0 | U19: =T16+T17+T18+T19 -> 0 | W19: omegabv | X19: =T19/(F49-1) -> 0 | Y19: =X19/4 -> 0
B20: omegatxfv | D20: =AVERAGE('SA data'!P2:P137)/AVERAGE('SA data'!$A$2:$A$137) -> 0.094737194 | E20: =AVERAGE('SA data'!P78:P137)/AVERAGE('SA data'!$A$78:$A$137) -> 0.085745631 | F20: =(2/3)*F18 -> 0.1025 | I20: crh | K20: =ss!E33*K3 -> 1.445097 | L20: =F33*L3 -> 1.351273
B21: omegantxv | D21: =AVERAGE('SA data'!Q2:Q137)/AVERAGE('SA data'!$A$2:$A$137) -> 0.048005061 | E21: =AVERAGE('SA data'!Q78:Q137)/AVERAGE('SA data'!$A$78:$A$137) -> 0.046501756 | F21: =0.25*F17 -> 0.05125 | I21: crf | K21: =ss!E34*K3 -> 6.5923045 | L21: =F34*L3 -> 6.1651832 | Q21: =V21/$U$19 -> #DIV/0! | R21: omegarev | T21: =T22+T25 -> 0 | V21: =U19 -> 0
I22: lendg | K22: =ss!E35*K3 -> 1.0702495 | L22: =F35*L3 -> 1.0134548 | Q22: =V22/$U$19 -> #DIV/0! | R22: omegatxv | T22: =T23+T24 -> 0 | V22: =T22/T21*V21 -> #DIV/0!
I23: oa | K23: =ss!E36*K3 -> 4.4979798 | L23: =F36*L3 -> 4.2227282 | Q23: =V23/$U$19 -> #DIV/0! | R23: omegatxhv | T23: ='SA data'!O167 -> 0 | V23: =T23/T22*V22 -> #DIV/0!
I24: nw | K24: =ss!E37*K3 -> 1.4515888 | L24: =F37*L3 -> 1.351273 | Q24: =V24/$U$19 -> #DIV/0! | R24: omegatxfv | T24: ='SA data'!P167 -> 0 | V24: =T24/T22*V22 -> #DIV/0!
I25: loan | K25: =ss!E38*K3 -> 0.4972363 | L25: =F38*L3 -> 0.50672739 | Q25: =V25/$U$19 -> #DIV/0! | R25: omegantxv | T25: ='SA data'!Q167 -> 0 | U25: =T22+T25 -> 0 | V25: =T25/T21*V21 -> #DIV/0!
B26: omegarevv | D26: =ss!D12+D13+D14+D15 -> 0.21978117 | E26: =E12+E13+E14+E15 -> 0.21695581 | F26: =F12+F13+F14+F15 -> 0.205 | I26: depp | K26: =ss!E39*K3 -> 9.7400643 | L26: =F39*L3 -> 9.1210929 | U26: =U25-U19 -> 0
B27: omegatxv | D27: =0.75*D26 -> 0.16483588 | E27: =0.75*E26 -> 0.16271686 | F27: =0.75*F26 -> 0.15375 | I27: depg | K27: =E41*K3 -> 0 | L27: =F41*L3 -> 0
B28: omegantxv | D28: =0.25*D26 -> 0.054945292 | E28: =0.25*E26 -> 0.054238952 | F28: =0.25*F26 -> 0.05125 | I28: cash | K28: =E42*K3 -> 0 | L28: =F42*L3 -> 0
B29: omegatxhv | D29: =(1/3)*D27 -> 0.054945292 | E29: =(1/3)*E27 -> 0.054238952 | F29: =(1/3)*F27 -> 0.05125 | I29: ol | K29: =ss!E40*K3 -> 1.9167413 | L29: =F40*L3 -> 1.7735459
B30: omegatxfv | D30: =(2/3)*D27 -> 0.10989058 | E30: =(2/3)*E27 -> 0.1084779 | F30: =(2/3)*F27 -> 0.1025 | I30: ms | K30: =E44*K3 -> 1.8061949 | L30: =F44*L3 -> 1.6933246
Q31: cg | R31: =F12*L3 -> 0.16890913
B32: omegacrv | E32: =ss!E34+ss!E33 -> 4.4610609 | F32: =F34+F33 -> 4.45 | I32: wl/pc | J32: =(J11*D54)/(J4*D62) -> 1.2431443 | K32: =(K11*E54)/(K4*E62) -> 1.1803511 | L32: =(L11*F54)/(L4*F62) -> 1.1111111 | Q32: ig | R32: =F13*L3 -> 0.067563651
B33: omegacrhv | E33: =AVERAGE('SA data'!AJ78:AJ137)/AVERAGE('SA data'!A78:A137) -> 0.80208335 | F33: =MROUND(ss!E33,0.05) -> 0.8 | I33: tx/c | J33: =J13/J4 -> 0.30737217 | K33: =K13/K4 -> 0.28809452 | L33: =L13/L4 -> 0.25625 | Q33: tr | R33: =F14*L3 -> 0.076009108
B34: omegacrfv | E34: =AVERAGE('SA data'!AK78:AK137)/AVERAGE('SA data'!A78:A137) -> 3.6589776 | F34: =MROUND(ss!E34,0.05) -> 3.65 | I34: txh/c | J34: =J14/J4 -> 0.10245739 | K34: =K14/K4 -> 0.096031506 | L34: =L14/L4 -> 0.085416667 | Q34: txh | R34: =F19*L3 -> 0.086565928
B35: omegalendgv | E35: =AVERAGE('SA data'!AL78:AL137)/AVERAGE('SA data'!A78:A137) -> 0.59402881 | F35: =MROUND(ss!E35,0.05) -> 0.6 | I35: tr/c | J35: =J17/J4 -> 0.069561854 | K35: =K17/K4 -> 0.077816591 | L35: =L17/L4 -> 0.075 | Q35: txf | R35: =F20*L3 -> 0.17313186
B36: omegaoav | E36: =AVERAGE('SA data'!AM78:AM137)/AVERAGE('SA data'!A78:A137) -> 2.4965484 | F36: =MROUND(ss!E36,0.05) -> 2.5 | Q36: ntx | R36: =F21*L3 -> 0.086565928
B37: omeganwv | E37: =AVERAGE('SA data'!AN78:AN137)/AVERAGE('SA data'!$A78:$A137) -> 0.80568653 | F37: =MROUND(ss!E37,0.05) -> 0.8 | I37: v/nw | K37: =K3/K24 -> 1.2411775 | L37: =L3/L24 -> 1.25 | Q37: fp | R37: =R34+R35+R36 -> 0.34626371 | T37: =R31/R37 -> 0.48780488 | U37: =R32/R37 -> 0.19512195 | V37: =R33/R37 -> 0.2195122 | W37: =R34/R37 -> 0.25 | X37: =R35/R37 -> 0.5 | Y37: =R36/R37 -> 0.25
B38: omegaloanv | E38: =AVERAGE('SA data'!AO78:AO137)/AVERAGE('SA data'!$A78:$A137) -> 0.2759849 | F38: =MROUND(ss!E38,0.05) -> 0.3 | I38: w*l/nw | K38: =(K11*E54)/K24 -> 0.82745167 | L38: =(L11*F54)/L24 -> 0.83333333
B39: omegadeppv | E39: =AVERAGE('SA data'!AP78:AP137)/AVERAGE('SA data'!$A78:$A137) -> 5.406103 | F39: =MROUND(ss!E39,0.05) -> 5.4 | I39: rb*fd/nw | K39: =(E61*(K25+K26))/K24 -> 0.11475745 | L39: =(F61*(L25+L26))/L24 -> 0.10700893
B40: omegaolv | E40: =AVERAGE('SA data'!AQ78:AQ137)/AVERAGE('SA data'!$A78:$A137) -> 1.0638637 | F40: =MROUND(ss!E40,0.05) -> 1.05
...

Sheet DATA
B1: Nominal | I1: Real | P1: Implicit deflator | W1: Nominal | Z1: 1 | AA1: 0.059 | AB1: 0.027 | AC1: 0.004 | AD1: =SUM(AA1:AC1) -> 0.09 | AG1: 0.767 | AH1: =Z1-AG1 -> 0.233 | AJ1: 0.8 | AK1: 0.1 | AL1: 0.1 | AU1: Nominal | BD1: Real | BM1: FISS & MSB (1.19, 1.19b, 1.19b) | BP1: Nominal | BZ1: Real Total asset/Liabilities | CK1: Real | CQ1: https://fred.stlouisfed.org/series/WTISPLC | CR1: Crude Oil Prices: Brent - Europe (DCOILBRENTEU) | FRED | St. Louis Fed
B2: Household consumption | C2: Gov consumption | D2: GFCF | E2: Change in Stock | F2: Exports of G&S | G2: Imports G&S | H2: GDP | I2: Household consumption | J2: Gov consumption | K2: GFCF | L2: Change in Stock | M2: Exports of G&S | N2: Imports G&S | O2: GDP | P2: Household consumption | Q2: Gov consumption | R2: GFCF | S2: Exports of G&S | T2: Imports G&S | U2: GDP | W2: Wage per worker | X2: Labour hour | Z2: Hradline CPI | AA2: Fuel price index | AB2: Electricity price index | AC2: Gas price index | AD2: Energy price index | AF2: DOSM Core CPI | AG2: Adjusted Core CPI | AH2: Non-coreCPI | AI2: Headline | AJ2: Core | AK2: Energy | AL2: Temporary | AN2: OPR | AO2: 3 mths deposit rate | AP2: Average lending rate (ALR) | AQ2: Spread (Risk premium) | AR2: MYRUSD | AS2: NEER, BIS | AU2: Household tax | AV2: Firm tax | AW2: Non-tax revenue | AX2: Transfer | AY2: Interest charges | AZ2: Fed gov consumption | BA2: Fed gov investment | BB2: Overall deficit | BC2: Deficit, % | BD2: Household tax | BE2: Firm tax | BF2: Non-tax revenue | BG2: Transfer | BH2: Interest charges | BI2: Fed gov consumption | BJ2: Fed gov investment | BK2: Overall deficit | BM2: Share of household consumption credit | BN2: Credit for consumption | BO2: Total credit | BP2: Total asset/Liabilities | BQ2: Lending to Government | BR2: Credit to Private sector | BS2: Credit to house-holds | BT2: Credit to firms | BU2: Other asset | BV2: Networth | BW2: External borrowings | BX2: Deposits | BY2: Other liabiities | BZ2: Total asset/Liabilities | CA2: Lending to Government | CB2: Credit to Private sector | CC2: Credit to house-holds | CD2: Credit to firms | CE2: Other asset | CF2: Networth | CG2: External borrowings | CH2: Deposits | CI2: Other liabiities | CK2: Global trade, sa | CL2: Global GDP, sa | CM2: US export G&S deflator, sa | CN2: FFR | CO2: US CPI | CP2: Global commodity price | CQ2: Crude oil WTI | CR2: Crude oil Brent
A3: 33298 | B3: 21813 | C3: 3672 | D3: 13437.633 | E3: =H3-B3-C3-D3-F3+G3 -> -2283.1171 | F3: 22804.771 | G3: 24503.287 | H3: 34941 | I3: 40020 | J3: 6650 | K3: 22298.503 | L3: =O3-I3-J3-K3-M3+N3 -> 1807.0153 | M3: 43385.472 | N3: 39647.99 | O3: 74513 | P3: =B3/I3*100 -> 54.505247 | Q3: =C3/J3*100 -> 55.218045 | R3: =D3/K3*100 -> 60.262492 | S3: =F3/M3*100 -> 52.563151 | T3: =G3/N3*100 -> 61.802093 | U3: =H3/O3*100 -> 46.892489 | W3: 1974.8527 | X3: 4844.7118 | Z3: 58.429371 | AA3: 59 | AB3: 93 | AC3: 67.666667 | AD3: =SUMPRODUCT($AA$1:$AC$1,AA3:AC3)/SUM($AA$1:$AC$1) -> 69.585185 | AF3: 67.076243 | AG3: 67.076243 | AH3: =(Z3-0.8*AG3)/0.2 -> 23.84188 | AN3: 6.5866667 | AO3: 6.49 | AP3: 9.1 | AQ3: =AP3-AN3 -> 2.5133333 | AR3: 2.7182 | AS3: 138.34506 | AU3: 1566.8777 | AV3: 4587.7392 | AW3: 1410.3143 | AX3: 681.75531 | AY3: 976.30021 | AZ3: 3807.6234 | BA3: 787.71857 | BB3: =AU3+AV3+AW3-AX3-AY3-AZ3-BA3 -> 1311.5337 | BC3: =BB3/H3*100 -> 3.7535665 | BD3: =AU3/$U3*100 -> 3341.4258 | BE3: =AV3/$U3*100 -> 9783.5269 | BF3: =AW3/$U3*100 -> 3007.5484 | BG3: =AX3/$U3*100 -> 1453.8689 | BH3: =AY3/$U3*100 -> 2081.997 | BI3: =AZ3/$U3*100 -> 8119.9006 | BJ3: =BA3/$U3*100 -> 1679.8396 | BK3: =BD3+BE3+BF3-BG3-BH3-BI3-BJ3 -> 2796.895 | CK3: 48.625969 | CL3: 68.775947 | CM3: 84.591 | CN3: 6.43 | CO3: 61.793 | CQ3: 21.781 | CR3: 20.82
A4: 33390 | B4: 18721 | C4: 3991 | D4: 13098.858 | E4: =H4-B4-C4-D4-F4+G4 -> 1771.0321 | F4: 22837.551 | G4: 25450.441 | H4: 34969 | I4: 33768 | J4: 7088 | K4: 21428.75 | L4: =O4-I4-J4-K4-M4+N4 -> 10203.238 | M4: 43069.236 | N4: 40861.223 | O4: 74696 | P4: =B4/I4*100 -> 55.440062 | Q4: =C4/J4*100 -> 56.306433 | R4: =D4/K4*100 -> 61.127496 | S4: =F4/M4*100 -> 53.025207 | T4: =G4/N4*100 -> 62.28507 | U4: =H4/O4*100 -> 46.815091 | W4: 1994.2184 | X4: 4744.3815 | Z4: 59.186543 | AA4: 59 | AB4: 93 | AC4: 68 | AD4: =SUMPRODUCT($AA$1:$AC$1,AA4:AC4)/SUM($AA$1:$AC$1) -> 69.6 | AF4: 67.734365 | AG4: 67.734365 | AH4: =(Z4-0.8*AG4)/0.2 -> 24.995253 | AN4: 6.8833333 | AO4: 6.7333333 | AP4: 9.3 | AQ4: =AP4-AN4 -> 2.4166667 | AR4: 2.7621 | AS4: 141.12479 | AU4: 1294.5311 | AV4: 5019.3896 | AW4: 1565.9482 | AX4: 464.8135 | AY4: 1868.2836 | AZ4: 3675.7309 | BA4: 1092.2764 | BB4: =AU4+AV4+AW4-AX4-AY4-AZ4-BA4 -> 778.76445 | BC4: =BB4/H4*100 -> 2.2270138 | BD4: =AU4/$U4*100 -> 2765.2005 | BE4: =AV4/$U4*100 -> 10721.734 | BF4: =AW4/$U4*100 -> 3344.9645 | BG4: =AX4/$U4*100 -> 992.87109 | BH4: =AY4/$U4*100 -> 3990.7721 | BI4: =AZ4/$U4*100 -> 7851.5941 | BJ4: =BA4/$U4*100 -> 2333.1717 | BK4: =BD4+BE4+BF4-BG4-BH4-BI4-BJ4 -> 1663.4902 | CK4: 50.008921 | CL4: 69.402571 | CM4: 84.115 | CN4: 5.86 | CO4: 62.27 | CQ4: 20.753 | CR4: 18.87
A5: 33482 | B5: 20857 | C5: 5052 | D5: 15269.136 | E5: =H5-B5-C5-D5-F5+G5 -> -722.07427 | F5: 27343.087 | G5: 27480.149 | H5: 40319 | I5: 38019 | J5: 9128 | K5: 25300.961 | L5: =O5-I5-J5-K5-M5+N5 -> 5074.1868 | M5: 50861.965 | N5: 43952.112 | O5: 84432 | P5: =B5/I5*100 -> 54.859412 | Q5: =C5/J5*100 -> 55.346188 | R5: =D5/K5*100 -> 60.350027 | S5: =F5/M5*100 -> 53.7594 | T5: =G5/N5*100 -> 62.522932 | U5: =H5/O5*100 -> 47.753222 | W5: 2069.3729 | X5: 4912.1779 | Z5: 59.47642 | AA5: 59 | AB5: 93 | AC5: 68 | AD5: =SUMPRODUCT($AA$1:$AC$1,AA5:AC5)/SUM($AA$1:$AC$1) -> 69.6 | AF5: 68.305718 | AG5: 68.305718 | AH5: =(Z5-0.8*AG5)/0.2 -> 24.159228 | AN5: 7.4066667 | AO5: 7.3266667 | AP5: 9.3 | AQ5: =AP5-AN5 -> 1.8933333 | AR5: 2.7756 | AS5: 140.05566 | AU5: 1532.4472 | AV5: 5056.6358 | AW5: 1270.9197 | AX5: 609.88596 | AY5: 1446.6994 | AZ5: 4381.2142 | BA5: 2699.7021 | BB5: =AU5+AV5+AW5-AX5-AY5-AZ5-BA5 -> -1277.4991 | BC5: =BB5/H5*100 -> -3.1684791 | BD5: =AU5/$U5*100 -> 3209.097 | BE5: =AV5/$U5*100 -> 10589.099 | BF5: =AW5/$U5*100 -> 2661.4323 | BG5: =AX5/$U5*100 -> 1277.1619 | BH5: =AY5/$U5*100 -> 3029.5326 | BI5: =AZ5/$U5*100 -> 9174.6988 | BJ5: =BA5/$U5*100 -> 5653.4451 | BK5: =BD5+BE5+BF5-BG5-BH5-BI5-BJ5 -> -2675.2103 | CK5: 51.228721 | CL5: 70.132529 | CM5: 83.542 | CN5: 5.65 | CO5: 62.83 | CQ5: 21.655 | CR5: 19.87
A6: 33573 | B6: 20709 | C6: 6837 | D6: 17261.737 | E6: =H6-B6-C6-D6-F6+G6 -> -1993.3961 | F6: 27957.658 | G6: 28081.999 | H6: 42690 | I6: 37877 | J6: 12378 | K6: 27787.64 | L6: =O6-I6-J6-K6-M6+N6 -> 289.93284 | M6: 51518.265 | N6: 44177.838 | O6: 85673 | P6: =B6/I6*100 -> 54.674341 | Q6: =C6/J6*100 -> 55.235095 | R6: =D6/K6*100 -> 62.120197 | S6: =F6/M6*100 -> 54.267468 | T6: =G6/N6*100 -> 63.565806 | U6: =H6/O6*100 -> 49.829001 | W6: 2226.5044 | X6: 4913.876 | Z6: 59.843581 | AA6: 59 | AB6: 93 | AC6: 68 | AD6: =SUMPRODUCT($AA$1:$AC$1,AA6:AC6)/SUM($AA$1:$AC$1) -> 69.6 | AF6: 68.669915 | AG6: 68.669915 | AH6: =(Z6-0.8*AG6)/0.2 -> 24.538245 | AN6: 7.71 | AO6: 7.8933333 | AP6: 9.69 | AQ6: =AP6-AN6 -> 1.98 | AR6: 2.7434 | AS6: 137.59667 | AU6: 1492.144 | AV6: 5280.2354 | AW6: 3975.8179 | AX6: 1023.5452 | AY6: 2756.7168 | AZ6: 6603.4314 | BA6: 3817.3029 | BB6: =AU6+AV6+AW6-AX6-AY6-AZ6-BA6 -> -3452.799 | BC6: =BB6/H6*100 -> -8.0880746 | BD6: =AU6/$U6*100 -> 2994.5292 | BE6: =AV6/$U6*100 -> 10596.711 | BF6: =AW6/$U6*100 -> 7978.9235 | BG6: =AX6/$U6*100 -> 2054.1155 | BH6: =AY6/$U6*100 -> 5532.3541 | BI6: =AZ6/$U6*100 -> 13252.185 | BJ6: =BA6/$U6*100 -> 7660.8055 | BK6: =BD6+BE6+BF6-BG6-BH6-BI6-BJ6 -> -6929.2961 | CK6: 52.115671 | CL6: 70.761915 | CM6: 83.691 | CN6: 4.82 | CO6: 63.325 | CQ6: 21.737 | CR6: 20.63
A7: 33664 | B7: 23814 | C7: 3698 | D7: 15708.593 | E7: =H7-B7-C7-D7-F7+G7 -> -2628.7459 | F7: 24195.856 | G7: 26006.703 | H7: 38781 | I7: 42183 | J7: 6597 | K7: 25643.278 | L7: =O7-I7-J7-K7-M7+N7 -> 3401.8332 | M7: 47408.986 | N7: 43408.098 | O7: 81826 | P7: =B7/I7*100 -> 56.454022 | Q7: =C7/J7*100 -> 56.055783 | R7: =D7/K7*100 -> 61.258133 | S7: =F7/M7*100 -> 51.036433 | T7: =G7/N7*100 -> 59.9121 | U7: =H7/O7*100 -> 47.394471 | W7: 2193.984 | X7: 4951.0638 | Z7: 60.951382 | AA7: 59 | AB7: 93 | AC7: 68 | AD7: =SUMPRODUCT($AA$1:$AC$1,AA7:AC7)/SUM($AA$1:$AC$1) -> 69.6 | AF7: 69.678963 | AG7: 69.678963 | AH7: =(Z7-0.8*AG7)/0.2 -> 26.041058 | AI7: =(Z7/Z3-1)*100 -> 4.3163419 | AJ7: =(AF7/AF3-1)*100*$AJ$1 -> 3.1041926 | AK7: =(AD7/AD3-1)*100*$AK$1 -> 0.0021290185 | AL7: =AI7-AJ7-AK7 -> 1.2100202 | AN7: 7.93 | AO7: 7.8866667 | AP7: 9.91 | AQ7: =AP7-AN7 -> 1.98 | AR7: 2.6227 | AS7: 143.47687 | AU7: 1822.2616 | AV7: 5106.571 | AW7: 1790.6209 | AX7: 771.91068 | AY7: 1011.7617 | AZ7: 4411.9613 | BA7: 789.68857 | BB7: =AU7+AV7+AW7-AX7-AY7-AZ7-BA7 -> 1734.1312 | BC7: =BB7/H7*100 -> 4.4715999 | BD7: =AU7/$U7*100 -> 3844.8822 | BE7: =AV7/$U7*100 -> 10774.613 | BF7: =AW7/$U7*100 -> 3778.1219 | BG7: =AX7/$U7*100 -> 1628.6935 | BH7: =AY7/$U7*100 -> 2134.7674 | BI7: =AZ7/$U7*100 -> 9309.0211 | BJ7: =BA7/$U7*100 -> 1666.204 | BK7: =BD7+BE7+BF7-BG7-BH7-BI7-BJ7 -> 3658.9314 | CK7: 52.952021 | CL7: 71.741311 | CM7: 83.551 | CN7: 4.02 | CO7: 63.809 | CP7: 45.563089 | CQ7: 18.91 | CR7: 17.95
A8: 33756 | B8: 20178 | C8: 4612 | D8: 14487.337 | E8: =H8-B8-C8-D8-F8+G8 -> 119.27277 | F8: 26452.19 | G8: 25939.799 | H8: 39909 | I8: 35487 | J8: 8257 | K8: 23871.627 | L8: =O8-I8-J8-K8-M8+N8 -> 6598.6375 | M8: 52164.087 | N8: 43615.352 | O8: 82763 | P8: =B8/I8*100 -> 56.860259 | Q8: =C8/J8*100 -> 55.855638 | R8: =D8/K8*100 -> 60.688519 | S8: =F8/M8*100 -> 50.70958 | T8: =G8/N8*100 -> 59.474012 | U8: =H8/O8*100 -> 48.220823 | W8: 2149.3003 | X8: 4921.7585 | Z8: 61.899059 | AA8: 59 | AB8: 93 | AC8: 68 | AD8: =SUMPRODUCT($AA$1:$AC$1,AA8:AC8)/SUM($AA$1:$AC$1) -> 69.6 | AF8: 70.352827 | AG8: 70.352827 | AH8: =(Z8-0.8*AG8)/0.2 -> 28.083987 | AI8: =(Z8/Z4-1)*100 -> 4.5829947 | AJ8: =(AF8/AF4-1)*100*$AJ$1 -> 3.0926242 | AK8: =(AD8/AD4-1)*100*$AK$1 -> 0 | AL8: =AI8-AJ8-AK8 -> 1.4903706 | AN8: 7.9566667 | AO8: 8.0166667 | AP8: 10.17 | AQ8: =AP8-AN8 -> 2.2133333 | AR8: 2.531 | AS8: 149.03633 | AU8: 1505.6862 | AV8: 5583.5346 | AW8: 1993.2345 | AX8: 482.45556 | AY8: 1936.1441 | AZ8: 4392.722 | BA8: 1095.0081 | BB8: =AU8+AV8+AW8-AX8-AY8-AZ8-BA8 -> 1176.1256 | BC8: =BB8/H8*100 -> 2.9470185 | BD8: =AU8/$U8*100 -> 3122.4814 | BE8: =AV8/$U8*100 -> 11579.094 | BF8: =AW8/$U8*100 -> 4133.5555 | BG8: =AX8/$U8*100 -> 1000.5129 | BH8: =AY8/$U8*100 -> 4015.1618 | BI8: =AZ8/$U8*100 -> 9109.5957 | BJ8: =BA8/$U8*100 -> 2270.82 | BK8: =BD8+BE8+BF8-BG8-BH8-BI8-BJ8 -> 2439.0409 | CK8: 53.652745 | CL8: 72.670182 | CM8: 83.628 | CN8: 3.77 | CO8: 64.26 | CP8: 47.754752 | CQ8: 21.186 | CR8: 20.01
A9: 33848 | B9: 22541 | C9: 4949 | D9: 17758.006 | E9: =H9-B9-C9-D9-F9+G9 -> -1078.5134 | F9: 28698.855 | G9: 28030.347 | H9: 44838 | I9: 39915 | J9: 8796 | K9: 28817.794 | L9: =O9-I9-J9-K9-M9+N9 -> 4734.4701 | M9: 55379.164 | N9: 46876.428 | O9: 90766 | P9: =B9/I9*100 -> 56.472504 | Q9: =C9/J9*100 -> 56.264211 | R9: =D9/K9*100 -> 61.621669 | S9: =F9/M9*100 -> 51.822479 | T9: =G9/N9*100 -> 59.796253 | U9: =H9/O9*100 -> 49.399555 | W9: 2227.1443 | X9: 4875.7835 | Z9: 62.499898 | AA9: 59 | AB9: 93 | AC9: 68 | AD9: =SUMPRODUCT($AA$1:$AC$1,AA9:AC9)/SUM($AA$1:$AC$1) -> 69.6 | AF9: 70.80095 | AG9: 70.80095 | AH9: =(Z9-0.8*AG9)/0.2 -> 29.295691 | AI9: =(Z9/Z5-1)*100 -> 5.0834913 | AJ9: =(AF9/AF5-1)*100*$AJ$1 -> 2.9224289 | AK9: =(AD9/AD5-1)*100*$AK$1 -> 0 | AL9: =AI9-AJ9-AK9 -> 2.1610624 | AN9: 7.8433333 | AO9: 7.97 | AP9: 10.3 | AQ9: =AP9-AN9 -> 2.4566667 | AR9: 2.5002 | AS9: 146.68425 | AU9: 1782.6988 | AV9: 5659.2796 | AW9: 1617.5789 | AX9: 603.58553 | AY9: 1499.2469 | AZ9: 5194.751 | BA9: 2706.4538 | BB9: =AU9+AV9+AW9-AX9-AY9-AZ9-BA9 -> -944.47999 | BC9: =BB9/H9*100 -> -2.1064276 | BD9: =AU9/$U9*100 -> 3608.7346 | BE9: =AV9/$U9*100 -> 11456.135 | BF9: =AW9/$U9*100 -> 3274.4807 | BG9: =AX9/$U9*100 -> 1221.8441 | BH9: =AY9/$U9*100 -> 3034.9402 | BI9: =AZ9/$U9*100 -> 10515.785 | BJ9: =BA9/$U9*100 -> 5478.7008 | BK9: =BD9+BE9+BF9-BG9-BH9-BI9-BJ9 -> -1911.9201 | CK9: 54.35499 | CL9: 73.535547 | CM9: 83.619 | CN9: 3.26 | CO9: 64.64 | CP9: 48.522837 | CQ9: 21.67 | CR9: 20.09
A10: 33939 | B10: 21690 | C10: 7455 | D10: 18331.964 | E10: =H10-B10-C10-D10-F10+G10 -> -3285.1689 | F10: 30549.236 | G10: 27777.031 | H10: 46964 | I10: 39059 | J10: 13309 | K10: 29010.296 | L10: =O10-I10-J10-K10-M10+N10 -> -1241.7934 | M10: 57665.595 | N10: 45486.098 | O10: 92316 | P10: =B10/I10*100 -> 55.531376 | Q10: =C10/J10*100 -> 56.014727 | R10: =D10/K10*100 -> 63.191235 | S10: =F10/M10*100 -> 52.976538 | T10: =G10/N10*100 -> 61.067079 | U10: =H10/O10*100 -> 50.873088 | W10: 2403.8501 | X10: 4997.5792 | Z10: 62.74584 | AA10: 59 | AB10: 93 | AC10: 68 | AD10: =SUMPRODUCT($AA$1:$AC$1,AA10:AC10)/SUM($AA$1:$AC$1) -> 69.6 | AF10: 71.024095 | AG10: 71.024095 | AH10: =(Z10-0.8*AG10)/0.2 -> 29.632818 | AI10: =(Z10/Z6-1)*100 -> 4.84974 | AJ10: =(AF10/AF6-1)*100*$AJ$1 -> 2.7426035 | AK10: =(AD10/AD6-1)*100*$AK$1 -> 0 | AL10: =AI10-AJ10-AK10 -> 2.1071366 | AN10: 7.9366667 | AO10: 7.8666667 | AP10: 10.27 | AQ10: =AP10-AN10 -> 2.3333333 | AR10: 2.5337 | AS10: 148.07411 | AU10: 1734.3533 | AV10: 5577.6148 | AW10: 5076.5657 | AX10: 885.04823 | AY10: 2856.8472 | AZ10: 8028.5656 | BA10: 3826.8495 | BB10: =AU10+AV10+AW10-AX10-AY10-AZ10-BA10 -> -3208.7768 | BC10: =BB10/H10*100 -> -6.832418 | BD10: =AU10/$U10*100 -> 3409.1765 | BE10: =AV10/$U10*100 -> 10963.783 | BF10: =AW10/$U10*100 -> 9978.8825 | BG10: =AX10/$U10*100 -> 1739.7179 | BH10: =AY10/$U10*100 -> 5615.6356 | BI10: =AZ10/$U10*100 -> 15781.557 | BJ10: =BA10/$U10*100 -> 7522.3456 | BK10: =BD10+BE10+BF10-BG10-BH10-BI10-BJ10 -> -6307.415 | CK10: 55.138063 | CL10: 74.585097 | CM10: 83.466 | CN10: 3.03 | CO10: 65.114 | CP10: 46.85093 | CQ10: 20.479 | CR10: 19.22
A11: 34029 | B11: 24281 | C11: 3758 | D11: 17310.87 | E11: =H11-B11-C11-D11-F11+G11 -> -2089.8982 | F11: 28881.058 | G11: 28037.03 | H11: 44104 | I11: 41328 | J11: 6453 | K11: 27566.524 | L11: =O11-I11-J11-K11-M11+N11 -> 5107.8074 | M11: 52922.058 | N11: 44971.389 | O11: 88406 | P11: =B11/I11*100 -> 58.751936 | Q11: =C11/J11*100 -> 58.236479 | R11: =D11/K11*100 -> 62.796709 | S11: =F11/M11*100 -> 54.572818 | T11: =G11/N11*100 -> 62.34415 | U11: =H11/O11*100 -> 49.888017 | W11: 2253.7762 | X11: 4946.9225 | Z11: 63.605043 | AA11: 59 | AB11: 93 | AC11: 68 | AD11: =SUMPRODUCT($AA$1:$AC$1,AA11:AC11)/SUM($AA$1:$AC$1) -> 69.6 | AF11: 71.836605 | AG11: 71.836605 | AH11: =(Z11-0.8*AG11)/0.2 -> 30.678796 | AI11: =(Z11/Z7-1)*100 -> 4.3537338 | AJ11: =(AF11/AF7-1)*100*$AJ$1 -> 2.4772375 | AK11: =(AD11/AD7-1)*100*$AK$1 -> 0 | AL11: =AI11-AJ11-AK11 -> 1.8764963 | AN11: 7.6466667 | AO11: 7.5566667 | AP11: 10.22 | AQ11: =AP11-AN11 -> 2.5733333 | AR11: 2.6106 | AS11: 145.4013 | AU11: 2220.7465 | AV11: 5386.6956 | AW11: 1654.2836 | AX11: 819.86224 | AY11: 992.64576 | AZ11: 4410.5546 | BA11: 855.54286 | BB11: =AU11+AV11+AW11-AX11-AY11-AZ11-BA11 -> 2183.1203 | BC11: =BB11/H11*100 -> 4.9499372 | BD11: =AU11/$U11*100 -> 4451.4629 | BE11: =AV11/$U11*100 -> 10797.574 | BF11: =AW11/$U11*100 -> 3315.994 | BG11: =AX11/$U11*100 -> 1643.4052 | BH11: =AY11/$U11*100 -> 1989.7479 | BI11: =AZ11/$U11*100 -> 8840.9099 | BJ11: =BA11/$U11*100 -> 1714.9266 | BK11: =BD11+BE11+BF11-BG11-BH11-BI11-BJ11 -> 4376.0415 | CK11: 56.014871 | CL11: 75.277223 | CM11: 83.568 | CN11: 3.04 | CO11: 65.563 | CP11: 46.327112 | CQ11: 19.825 | CR11: 18.24
A12: 34121 | B12: 22228 | C12: 5831 | D12: 19413.032 | E12: =H12-B12-C12-D12-F12+G12 -> -802.09939 | F12: 32417.921 | G12: 32011.853 | H12: 47076 | I12: 37957 | J12: 10148 | K12: 30316.966 | L12: =O12-I12-J12-K12-M12+N12 -> 7350.2101 | M12: 58415.867 | N12: 51003.044 | O12: 93185 | P12: =B12/I12*100 -> 58.561003 | Q12: =C12/J12*100 -> 57.459598 | R12: =D12/K12*100 -> 64.033556 | S12: =F12/M12*100 -> 55.495061 | T12: =G12/N12*100 -> 62.764594 | U12: =H12/O12*100 -> 50.51886 | W12: 2279.1197 | X12: 4986.6827 | Z12: 64.055098 | AA12: 59 | AB12: 93 | AC12: 68 | AD12: =SUMPRODUCT($AA$1:$AC$1,AA12:AC12)/SUM($AA$1:$AC$1) -> 69.6 | AF12: 72.172011 | AG12: 72.172011 | AH12: =(Z12-0.8*AG12)/0.2 -> 31.587448 | AI12: =(Z12/Z8-1)*100 -> 3.4831535 | AJ12: =(AF12/AF8-1)*100*$AJ$1 -> 2.0686406 | AK12: =(AD12/AD8-1)*100*$AK$1 -> 0 | AL12: =AI12-AJ12-AK12 -> 1.4145128 | AN12: 7.3066667 | AO12: 7.2466667 | AP12: 10.16 | AQ12: =AP12-AN12 -> 2.8533333 | AR12: 2.5713 | AS12: 143.26304 | AU12: 1835.7548 | AV12: 5955.3032 | AW12: 1856.2452 | AX12: 511.94978 | AY12: 1899.563 | AZ12: 4429.9634 | BA12: 1186.3238 | BB12: =AU12+AV12+AW12-AX12-AY12-AZ12-BA12 -> 1619.5031 | BC12: =BB12/H12*100 -> 3.4401884 | BD12: =AU12/$U12*100 -> 3633.8008 | BE12: =AV12/$U12*100 -> 11788.277 | BF12: =AW12/$U12*100 -> 3674.3608 | BG12: =AX12/$U12*100 -> 1013.3835 | BH12: =AY12/$U12*100 -> 3760.1067 | BI12: =AZ12/$U12*100 -> 8768.9299 | BJ12: =BA12/$U12*100 -> 2348.279 | BK12: =BD12+BE12+BF12-BG12-BH12-BI12-BJ12 -> 3205.7395 | CK12: 56.861776 | CL12: 76.119003 | CM12: 83.798 | CN12: 3 | CO12: 66.061 | CP12: 47.382121 | CQ12: 19.76 | CR12: 18.25
A13: 34213 | B13: 24278 | C13: 5894 | D13: 20261.885 | E13: =H13-B13-C13-D13-F13+G13 -> 350.67263 | F13: 34656.164 | G13: 33860.721 | H13: 51580 | I13: 42124 | J13: 10189 | K13: 32247.112 | L13: =O13-I13-J13-K13-M13+N13 -> 6722.454 | M13: 62890.863 | N13: 53404.428 | O13: 100769 | P13: =B13/I13*100 -> 57.634603 | Q13: =C13/J13*100 -> 57.846697 | R13: =D13/K13*100 -> 62.833176 | S13: =F13/M13*100 -> 55.105245 | T13: =G13/N13*100 -> 63.404332 | U13: =H13/O13*100 -> 51.186377 | W13: 2334.8817 | X13: 5037.5947 | Z13: 64.442401 | AA13: 59 | AB13: 93 | AC13: 68 | AD13: =SUMPRODUCT($AA$1:$AC$1,AA13:AC13)/SUM($AA$1:$AC$1) -> 69.6 | AF13: 72.514126 | AG13: 72.514126 | AH13: =(Z13-0.8*AG13)/0.2 -> 32.155503 | AI13: =(Z13/Z9-1)*100 -> 3.1080097 | AJ13: =(AF13/AF9-1)*100*$AJ$1 -> 1.9357659 | AK13: =(AD13/AD9-1)*100*$AK$1 -> 0 | AL13: =AI13-AJ13-AK13 -> 1.1722438 | AN13: 6.94 | AO13: 6.8566667 | AP13: 9.93 | AQ13: =AP13-AN13 -> 2.99 | AR13: 2.5553 | AS13: 144.01143 | AU13: 2162.0317 | AV13: 5954.9107 | AW13: 1506.0386 | AX13: 640.13578 | AY13: 1470.9205 | AZ13: 5218.8345 | BA13: 2932.1524 | BB13: =AU13+AV13+AW13-AX13-AY13-AZ13-BA13 -> -639.06219 | BC13: =BB13/H13*100 -> -1.2389728 | BD13: =AU13/$U13*100 -> 4223.842 | BE13: =AV13/$U13*100 -> 11633.78 | BF13: =AW13/$U13*100 -> 2942.2645 | BG13: =AX13/$U13*100 -> 1250.5979 | BH13: =AY13/$U13*100 -> 2873.6563 | BI13: =AZ13/$U13*100 -> 10195.749 | BJ13: =BA13/$U13*100 -> 5728.3843 | BK13: =BD13+BE13+BF13-BG13-BH13-BI13-BJ13 -> -1248.5005 | CK13: 57.458111 | CL13: 77.104476 | CM13: 83.741 | CN13: 3.06 | CO13: 66.43 | CP13: 46.698385 | CQ13: 17.796 | CR13: 16.49
A14: 34304 | B14: 26001 | C14: 7380 | D14: 23428.25 | E14: =H14-B14-C14-D14-F14+G14 -> -2783.4593 | F14: 34475.111 | G14: 36498.902 | H14: 52002 | I14: 45056 | J14: 13078 | K14: 36378.911 | L14: =O14-I14-J14-K14-M14+N14 -> -781.69003 | M14: 62935.038 | N14: 56975.259 | O14: 99691 | P14: =B14/I14*100 -> 57.708185 | Q14: =C14/J14*100 -> 56.430647 | R14: =D14/K14*100 -> 64.400636 | S14: =F14/M14*100 -> 54.778883 | T14: =G14/N14*100 -> 64.060967 | U14: =H14/O14*100 -> 52.163184 | W14: 2476.6207 | X14: 4973.5275 | Z14: 64.83051 | AA14: 59 | AB14: 91.666667 | AC14: 68 | AD14: =SUMPRODUCT($AA$1:$AC$1,AA14:AC14)/SUM($AA$1:$AC$1) -> 69.2 | AF14: 72.725912 | AG14: 72.725912 | AH14: =(Z14-0.8*AG14)/0.2 -> 33.248901 | AI14: =(Z14/Z10-1)*100 -> 3.3224044 | AJ14: =(AF14/AF10-1)*100*$AJ$1 -> 1.9168904 | AK14: =(AD14/AD10-1)*100*$AK$1 -> -0.057471264 | AL14: =AI14-AJ14-AK14 -> 1.4629853 | AN14: 6.5233333 | AO14: 6.4433333 | AP14: 9.82 | AQ14: =AP14-AN14 -> 3.2966667 | AR14: 2.5595 | AS14: 144.75982 | AU14: 2110.467 | AV14: 6274.0905 | AW14: 4774.4326 | AX14: 937.0522 | AY14: 2802.8707 | AZ14: 8082.6475 | BA14: 4145.981 | BB14: =AU14+AV14+AW14-AX14-AY14-AZ14-BA14 -> -2809.5612 | BC14: =BB14/H14*100 -> -5.4027945 | BD14: =AU14/$U14*100 -> 4045.8938 | BE14: =AV14/$U14*100 -> 12027.814 | BF14: =AW14/$U14*100 -> 9152.8779 | BG14: =AX14/$U14*100 -> 1796.3861 | BH14: =AY14/$U14*100 -> 5373.2737 | BI14: =AZ14/$U14*100 -> 15494.927 | BJ14: =BA14/$U14*100 -> 7948.0979 | BK14: =BD14+BE14+BF14-BG14-BH14-BI14-BJ14 -> -5386.0998 | CK14: 59.35085 | CL14: 78.078835 | CM14: 83.707 | CN14: 2.99 | CO14: 66.772 | CP14: 45.472073 | CQ14: 16.451 | CR14: 15.18
A15: 34394 | B15: 28387 | C15: 4453 | D15: 20911.531 | E15: =H15-B15-C15-D15-F15+G15 -> -4427.6264 | F15: 36539.212 | G15: 37654.117 | H15: 48209 | I15: 46771 | J15: 7392 | K15: 32418.232 | L15: =O15-I15-J15-K15-M15+N15 -> 1456.0638 | M15: 63907.536 | N15: 56399.832 | O15: 95545 | P15: =B15/I15*100 -> 60.693592 | Q15: =C15/J15*100 -> 60.240801 | R15: =D15/K15*100 -> 64.505463 | S15: =F15/M15*100 -> 57.175123 | T15: =G15/N15*100 -> 66.762817 | U15: =H15/O15*100 -> 50.456853 | W15: 2397.6399 | X15: 4832.536 | Z15: 66.206978 | AA15: 59 | AB15: 89 | AC15: 67 | AD15: =SUMPRODUCT($AA$1:$AC$1,AA15:AC15)/SUM($AA$1:$AC$1) -> 68.355556 | AF15: 73.300146 | AG15: 73.300146 | AH15: =(Z15-0.8*AG15)/0.2 -> 37.834309 | AI15: =(Z15/Z11-1)*100 -> 4.0907691 | AJ15: =(AF15/AF11-1)*100*$AJ$1 -> 1.6298554 | AK15: =(AD15/AD11-1)*100*$AK$1 -> -0.17879949 | AL15: =AI15-AJ15-AK15 -> 2.6397132 | AN15: 4.0466667 | AO15: 6.0133333 | AP15: 9.35 | AQ15: =AP15-AN15 -> 5.3033333 | AR15: 2.7306 | AS15: 137.59667 | AU15: 2531.0962 | AV15: 6433.4877 | AW15: 2019.9282 | AX15: 958.67224 | AY15: 944.02468 | AZ15: 4870.2946 | BA15: 935.65619 | BB15: =AU15+AV15+AW15-AX15-AY15-AZ15-BA15 -> 3275.8644 | BC15: =BB15/H15*100 -> 6.7951303 | BD15: =AU15/$U15*100 -> 5016.3577 | BE15: =AV15/$U15*100 -> 12750.474 | BF15: =AW15/$U15*100 -> 4003.2782 | BG15: =AX15/$U15*100 -> 1899.9842 | BH15: =AY15/$U15*100 -> 1870.9543 | BI15: =AZ15/$U15*100 -> 9652.3947 | BJ15: =BA15/$U15*100 -> 1854.3689 | BK15: =BD15+BE15+BF15-BG15-BH15-BI15-BJ15 -> 6492.4072 | CK15: 60.603953 | CL15: 79.203567 | CM15: 84.082 | CN15: 3.21 | CO15: 67.075 | CP15: 45.829922 | CQ15: 14.813 | CR15: 13.96
A16: 34486 | B16: 25074 | C16: 5253 | D16: 20558.4 | E16: =H16-B16-C16-D16-F16+G16 -> 996.15616 | F16: 40255.536 | G16: 40414.093 | H16: 51723 | I16: 41547 | J16: 8931 | K16: 31772.181 | L16: =O16-I16-J16-K16-M16+N16 -> 9516.2462 | M16: 70747.184 | N16: 62206.611 | O16: 100307 | P16: =B16/I16*100 -> 60.350928 | Q16: =C16/J16*100 -> 58.817602 | R16: =D16/K16*100 -> 64.705664 | S16: =F16/M16*100 -> 56.900549 | T16: =G16/N16*100 -> 64.96752 | U16: =H16/O16*100 -> 51.564696 | W16: 2443.2014 | X16: 5162.4223 | Z16: 66.209658 | AA16: 59 | AB16: 90 | AC16: 68 | AD16: =SUMPRODUCT($AA$1:$AC$1,AA16:AC16)/SUM($AA$1:$AC$1) -> 68.7 | AF16: 73.578579 | AG16: 73.578579 | AH16: =(Z16-0.8*AG16)/0.2 -> 36.733974 | AI16: =(Z16/Z12-1)*100 -> 3.363604 | AJ16: =(AF16/AF12-1)*100*$AJ$1 -> 1.5591289 | AK16: =(AD16/AD12-1)*100*$AK$1 -> -0.12931034 | AL16: =AI16-AJ16-AK16 -> 1.9337855 | AN16: 4.0666667 | AO16: 4.48 | AP16: 8.95 | AQ16: =AP16-AN16 -> 4.8833333 | AR16: 2.6326 | AS16: 141.09 | AU16: 2090.9604 | AV16: 7083.8008 | AW16: 2267.0499 | AX16: 590.33966 | AY16: 1806.52 | AZ16: 5049.1944 | BA16: 1297.4116 | BB16: =AU16+AV16+AW16-AX16-AY16-AZ16-BA16 -> 2698.3456 | BC16: =BB16/H16*100 -> 5.2169162 | BD16: =AU16/$U16*100 -> 4055.0232 | BE16: =AV16/$U16*100 -> 13737.695 | BF16: =AW16/$U16*100 -> 4396.5156 | BG16: =AX16/$U16*100 -> 1144.8524 | BH16: =AY16/$U16*100 -> 3503.4046 | BI16: =AZ16/$U16*100 -> 9791.9599 | BJ16: =BA16/$U16*100 -> 2516.085 | BK16: =BD16+BE16+BF16-BG16-BH16-BI16-BJ16 -> 5232.9321 | CK16: 62.407797 | CL16: 80.292642 | CM16: 84.411 | CN16: 3.94 | CO16: 67.526 | CP16: 48.167029 | CQ16: 17.777 | CR16: 16.1
A17: 34578 | B17: 27745 | C17: 5997 | D17: 25590.76 | E17: =H17-B17-C17-D17-F17+G17 -> 388.42583 | F17: 44100.42 | G17: 44673.606 | H17: 59148 | I17: 45802 | J17: 10271 | K17: 40083.16 | L17: =O17-I17-J17-K17-M17+N17 -> 7087.6281 | M17: 75751.095 | N17: 68651.883 | O17: 110343 | P17: =B17/I17*100 -> 60.575957 | Q17: =C17/J17*100 -> 58.387694 | R17: =D17/K17*100 -> 63.844169 | S17: =F17/M17*100 -> 58.217535 | T17: =G17/N17*100 -> 65.07266 | U17: =H17/O17*100 -> 53.603763 | W17: 2519.5274 | X17: 5350.4723 | Z17: 66.752108 | AA17: 59 | AB17: 89 | AC17: 68 | AD17: =SUMPRODUCT($AA$1:$AC$1,AA17:AC17)/SUM($AA$1:$AC$1) -> 68.4 | AF17: 74.124367 | AG17: 74.124367 | AH17: =(Z17-0.8*AG17)/0.2 -> 37.263072 | AI17: =(Z17/Z13-1)*100 -> 3.5841411 | AJ17: =(AF17/AF13-1)*100*$AJ$1 -> 1.7764714 | AK17: =(AD17/AD13-1)*100*$AK$1 -> -0.17241379 | AL17: =AI17-AJ17-AK17 -> 1.9800835 | AN17: 4.0533333 | AO17: 4.26 | AP17: 8.54 | AQ17: =AP17-AN17 -> 4.4866667 | AR17: 2.5712 | AS17: 141.26 | AU17: 2491.8157 | AV17: 7081.8228 | AW17: 1839.3264 | AX17: 732.0729 | AY17: 1398.8729 | AZ17: 5846.6837 | BA17: 3206.7202 | BB17: =AU17+AV17+AW17-AX17-AY17-AZ17-BA17 -> 228.61516 | BC17: =BB17/H17*100 -> 0.38651375 | BD17: =AU17/$U17*100 -> 4648.5835 | BE17: =AV17/$U17*100 -> 13211.429 | BF17: =AW17/$U17*100 -> 3431.3382 | BG17: =AX17/$U17*100 -> 1365.7118 | BH17: =AY17/$U17*100 -> 2609.6544 | BI17: =AZ17/$U17*100 -> 10907.226 | BJ17: =BA17/$U17*100 -> 5982.2669 | BK17: =BD17+BE17+BF17-BG17-BH17-BI17-BJ17 -> 426.49087 | CK17: 64.205576 | CL17: 81.108168 | CM17: 84.806 | CN17: 4.49 | CO17: 67.903 | CP17: 50.360795 | CQ17: 18.497 | CR17: 16.78
A18: 34669 | B18: 28348 | C18: 9678 | D18: 27481.338 | E18: =H18-B18-C18-D18-F18+G18 -> -2430.823 | F18: 46362.483 | G18: 47267.997 | H18: 62171 | I18: 47958 | J18: 16728 | K18: 42781.599 | L18: =O18-I18-J18-K18-M18+N18 -> -3115.3605 | M18: 78701.057 | N18: 71995.296 | O18: 111058 | P18: =B18/I18*100 -> 59.110055 | Q18: =C18/J18*100 -> 57.855093 | R18: =D18/K18*100 -> 64.236349 | S18: =F18/M18*100 -> 58.909606 | T18: =G18/N18*100 -> 65.654286 | U18: =H18/O18*100 -> 55.980659 | W18: 2684.4919 | X18: 5410.5365 | Z18: 67.290089 | AA18: 59 | AB18: 93 | AC18: 68 | AD18: =SUMPRODUCT($AA$1:$AC$1,AA18:AC18)/SUM($AA$1:$AC$1) -> 69.6 | AF18: 74.48447 | AG18: 74.48447 | AH18: =(Z18-0.8*AG18)/0.2 -> 38.512562 | AI18: =(Z18/Z14-1)*100 -> 3.7938599 | AJ18: =(AF18/AF14-1)*100*$AJ$1 -> 1.93445 | AK18: =(AD18/AD14-1)*100*$AK$1 -> 0.057803468 | AL18: =AI18-AJ18-AK18 -> 1.8016064 | AN18: 4.6333333 | AO18: 4.8166667 | AP18: 8.21 | AQ18: =AP18-AN18 -> 3.5766667 | AR18: 2.5607 | AS18: 140.96333 | AU18: 2409.1277 | AV18: 7364.8887 | AW18: 5832.6955 | AX18: 1043.9152 | AY18: 2665.5824 | AZ18: 9157.8273 | BA18: 4534.2121 | BB18: =AU18+AV18+AW18-AX18-AY18-AZ18-BA18 -> -1794.8251 | BC18: =BB18/H18*100 -> -2.8869169 | BD18: =AU18/$U18*100 -> 4303.5001 | BE18: =AV18/$U18*100 -> 13156.131 | BF18: =AW18/$U18*100 -> 10419.126 | BG18: =AX18/$U18*100 -> 1864.7784 | BH18: =AY18/$U18*100 -> 4761.6132 | BI18: =AZ18/$U18*100 -> 16358.913 | BJ18: =BA18/$U18*100 -> 8099.6047 | BK18: =BD18+BE18+BF18-BG18-BH18-BI18-BJ18 -> -3206.1521 | CK18: 65.831577 | CL18: 81.942238 | CM18: 85.341 | CN18: 5.17 | CO18: 68.248 | CP18: 51.088318 | CQ18: 17.657 | CR18: 16.56
... A25: 35309 | B25: 33994 | C25: 8152 | D25: 31805.016 | E25: =H25-B25-C25-D25-F25+G25 -> -1049.9796 | F25: 56802.94 | G25: 55136.976 | H25: 74567 | I25: 54119 | J25: 12614 | K25: 48429.756 | L25: =O25-I25-J25-K25-M25+N25 -> 4945.0807 | M25: 95620.408 | N25: 84944.245 | O25: 130784 | P25: =B25/I25*100 -> 62.81343 | Q25: =C25/J25*100 -> 64.626605 | R25: =D25/K25*100 -> 65.672467 | S25: =F25/M25*100 -> 59.40462 | T25: =G25/N25*100 -> 64.909607 | U25: =H25/O25*100 -> 57.015384 | W25: 3006.2437 | X25: 5604.3436 | Z25: 71.570776 | AA25: 59 | AB25: 88 | AC25: 68 | AD25: =SUMPRODUCT($AA$1:$AC$1,AA25:AC25)/SUM($AA$1:$AC$1) -> 68.1 | AF25: 78.514076 | AG25: 78.514076 | AH25: =(Z25-0.8*AG25)/0.2 -> 43.797578 | AI25: =(Z25/Z21-1)*100 -> 3.600103 | AJ25: =(AF25/AF21-1)*100*$AJ$1 -> 2.6083309 | AK25: =(AD25/AD21-1)*100*$AK$1 -> -0.21551724 | AL25: =AI25-AJ25-AK25 -> 1.2072894 | AN25: 6.9066667 | AO25: 7.22 | AP25: 10.14 | AQ25: =AP25-AN25 -> 3.2333333 | AR25: 2.4951 | AS25: 148.16 | AU25: 3368 | AV25: 8389 | AW25: 1695 | AX25: 959.3644 | AY25: 1394.7677 | AZ25: 7625.8679 | BA25: 4051 | BB25: =AU25+AV25+AW25-AX25-AY25-AZ25-BA25 -> -579 | BC25: =BB25/H25*100 -> -0.77648289 | BD25: =AU25/$U25*100 -> 5907.1776 | BE25: =AV25/$U25*100 -> 14713.573 | BF25: =AW25/$U25*100 -> 2972.8818 | BG25: =AX25/$U25*100 -> 1682.6413 | BH25: =AY25/$U25*100 -> 2446.3006 | BI25: =AZ25/$U25*100 -> 13375.106 | BJ25: =BA25/$U25*100 -> 7105.0999 | BK25: =BD25+BE25+BF25-BG25-BH25-BI25-BJ25 -> -1015.5154 | CK25: 74.947163 | CL25: 86.893889 | CM25: 85.274 | CN25: 5.31 | CO25: 70.617 | CP25: 56.909897 | CQ25: 22.423 | CR25: 20.86
A26: 35400 | B26: 36304 | C26: 10082 | D26: 37298.661 | E26: =H26-B26-C26-D26-F26+G26 -> -5975.9492 | F26: 58073.681 | G26: 57066.392 | H26: 78716 | I26: 58047 | J26: 15550 | K26: 54735.591 | L26: =O26-I26-J26-K26-M26+N26 -> -3173.3916 | M26: 95573.426 | N26: 88077.625 | O26: 132655 | P26: =B26/I26*100 -> 62.542423 | Q26: =C26/J26*100 -> 64.836013 | R26: =D26/K26*100 -> 68.143341 | S26: =F26/M26*100 -> 60.763419 | T26: =G26/N26*100 -> 64.79102 | U26: =H26/O26*100 -> 59.338887 | W26: 3236.7036 | X26: 5685.2538 | Z26: 71.854434 | AA26: 59 | AB26: 88 | AC26: 68 | AD26: =SUMPRODUCT($AA$1:$AC$1,AA26:AC26)/SUM($AA$1:$AC$1) -> 68.1 | AF26: 78.907436 | AG26: 78.907436 | AH26: =(Z26-0.8*AG26)/0.2 -> 43.642427 | AI26: =(Z26/Z22-1)*100 -> 3.3460856 | AJ26: =(AF26/AF22-1)*100*$AJ$1 -> 2.6142394 | AK26: =(AD26/AD22-1)*100*$AK$1 -> -0.21551724 | AL26: =AI26-AJ26-AK26 -> 0.94736342 | AN26: 7.0666667 | AO26: 7.21 | AP26: 10.21 | AQ26: =AP26-AN26 -> 3.1433333 | AR26: 2.5183 | AS26: 147.98 | AU26: 3257 | AV26: 9780 | AW26: 5358 | AX26: 1393.7515 | AY26: 2657.7597 | AZ26: 12045.489 | BA26: 5728 | BB26: =AU26+AV26+AW26-AX26-AY26-AZ26-BA26 -> -3430 | BC26: =BB26/H26*100 -> -4.3574369 | BD26: =AU26/$U26*100 -> 5488.8121 | BE26: =AV26/$U26*100 -> 16481.603 | BF26: =AW26/$U26*100 -> 9029.492 | BG26: =AX26/$U26*100 -> 2348.7995 | BH26: =AY26/$U26*100 -> 4478.9511 | BI26: =AZ26/$U26*100 -> 20299.486 | BJ26: =BA26/$U26*100 -> 9653.0291 | BK26: =BD26+BE26+BF26-BG26-BH26-BI26-BJ26 -> -5780.3579 | BM26: 0.12970698 | BN26: =BM26*BO26 -> 43227.508 | BO26: 333270.49 | BP26: 513968.42 | BQ26: 13850.228 | BR26: 319305.1 | BS26: =BM26*BR26 -> 41416.1 | BT26: =BR26-BS26 -> 277889 | BU26: 180813.09 | BV26: 40868.974 | BW26: 21226.688 | BX26: 358769.48 | BY26: 93103.276 | BZ26: =BP26/$U26*100 -> 866157.84 | CA26: =BQ26/$U26*100 -> 23340.897 | CB26: =BR26/$U26*100 -> 538104.3 | CC26: =BS26/$U26*100 -> 69795.884 | CD26: =BT26/$U26*100 -> 468308.41 | CE26: =BU26/$U26*100 -> 304712.64 | CF26: =BV26/$U26*100 -> 68873.847 | CG26: =BW26/$U26*100 -> 35771.97 | ... CI26: =BY26/$U26*100 -> 156900.95 | CK26: 76.798273 | CL26: 87.854615 | CM26: 84.399 | CN26: 5.28 | CO26: 71.019 | CP26: 58.251899 | CQ26: 24.667 | CR26: 23.58
A27: 35490 | B27: 37781 | C27: 5668 | D27: 31163.84 | E27: =H27-B27-C27-D27-F27+G27 -> -5018.1431 | F27: 55900.307 | G27: 53639.004 | H27: 71856 | I27: 57893 | J27: 8808 | K27: 46088.032 | L27: =O27-I27-J27-K27-M27+N27 -> 1178.9567 | M27: 97495.322 | N27: 84164.311 | O27: 127299 | P27: =B27/I27*100 -> 65.260049 | Q27: =C27/J27*100 -> 64.35059 | R27: =D27/K27*100 -> 67.618075 | S27: =F27/M27*100 -> 57.336399 | T27: =G27/N27*100 -> 63.731293 | U27: =H27/O27*100 -> 56.446634 | W27: 3161.2539 | X27: 5903.1293 | Z27: 72.878912 | AA27: 59 | AB27: 88 | AC27: 68 | AD27: =SUMPRODUCT($AA$1:$AC$1,AA27:AC27)/SUM($AA$1:$AC$1) -> 68.1 | AF27: 79.727141 | AG27: 79.727141 | AH27: =(Z27-0.8*AG27)/0.2 -> 45.485992 | AI27: =(Z27/Z23-1)*100 -> 3.1801178 | AJ27: =(AF27/AF23-1)*100*$AJ$1 -> 2.5389678 | AK27: =(AD27/AD23-1)*100*$AK$1 -> -0.1447178 | AL27: =AI27-AJ27-AK27 -> 0.78586778 | AN27: 7.0586667 | AO27: 7.2266667 | AP27: 10.15 | AQ27: =AP27-AN27 -> 3.0913333 | AR27: 2.4845 | AS27: 154.76333 | AU27: 3723 | AV27: 8534 | AW27: 2034 | AX27: 1288.381 | AY27: 890.13978 | AZ27: 6759.4792 | BA27: 1544 | BB27: =AU27+AV27+AW27-AX27-AY27-AZ27-BA27 -> 3809 | BC27: =BB27/H27*100 -> 5.3008795 | BD27: =AU27/$U27*100 -> 6595.6103 | BE27: =AV27/$U27*100 -> 15118.705 | BF27: =AW27/$U27*100 -> 3603.4036 | BG27: =AX27/$U27*100 -> 2282.4762 | BH27: =AY27/$U27*100 -> 1576.9581 | BI27: =AZ27/$U27*100 -> 11974.991 | BJ27: =BA27/$U27*100 -> 2735.327 | BK27: =BD27+BE27+BF27-BG27-BH27-BI27-BJ27 -> 6747.9666 | BM27: 0.12174573 | BN27: =BM27*BO27 -> 43794.584 | BO27: 359721.73 | BP27: 553444.67 | BQ27: 13749.253 | BR27: 344769.7 | BS27: =BM27*BR27 -> 41974.239 | BT27: =BR27-BS27 -> 302795.46 | BU27: 194925.72 | BV27: 46971.782 | BW27: 29059.668 | BX27: 378104.49 | BY27: 99308.728 | BZ27: =BP27/$U27*100 -> 980474.19 | CA27: =BQ27/$U27*100 -> 24357.968 | CB27: =BR27/$U27*100 -> 610788.78 | CC27: =BS27/$U27*100 -> 74360.925 | CD27: =BT27/$U27*100 -> 536427.85 | CE27: =BU27/$U27*100 -> 345327.44 | CF27: =BV27/$U27*100 -> 83214.497 | CG27: =BW27/$U27*100 -> 51481.668 | ... CI27: =BY27/$U27*100 -> 175933.84 | CK27: 78.793163 | CL27: 88.73199 | CM27: 84.16 | CN27: 5.28 | CO27: 71.298 | CP27: 56.059259 | CQ27: 22.79 | CR27: 21.22
A28: 35582 | B28: 35154 | C28: 7136 | D28: 36922.519 | E28: =H28-B28-C28-D28-F28+G28 -> -636.79911 | F28: 56697.884 | G28: 60135.604 | H28: 75138 | I28: 53465 | J28: 10860 | K28: 52749.99 | L28: =O28-I28-J28-K28-M28+N28 -> 13941.358 | M28: 96139.193 | N28: 94527.541 | O28: 132628 | P28: =B28/I28*100 -> 65.751426 | Q28: =C28/J28*100 -> 65.709024 | R28: =D28/K28*100 -> 69.99531 | S28: =F28/M28*100 -> 58.974787 | T28: =G28/N28*100 -> 63.61702 | U28: =H28/O28*100 -> 56.653195 | W28: 3206.1361 | X28: 6055.7736 | Z28: 72.894962 | AA28: 59 | AB28: 92 | AC28: 68 | AD28: =SUMPRODUCT($AA$1:$AC$1,AA28:AC28)/SUM($AA$1:$AC$1) -> 69.3 | AF28: 80.117734 | AG28: 80.117734 | AH28: =(Z28-0.8*AG28)/0.2 -> 44.003872 | AI28: =(Z28/Z24-1)*100 -> 2.4665771 | AJ28: =(AF28/AF24-1)*100*$AJ$1 -> 2.421912 | AK28: =(AD28/AD24-1)*100*$AK$1 -> 0.17621145 | AL28: =AI28-AJ28-AK28 -> -0.13154637 | AN28: 8.1946667 | AO28: 7.3266667 | AP28: 10.523333 | AQ28: =AP28-AN28 -> 2.3286667 | AR28: 2.5087 | AS28: 154.11667 | AU28: 2945 | AV28: 10483 | AW28: 2595 | AX28: 807.17555 | AY28: 1703.4039 | AZ28: 6508.4206 | BA28: 3255 | BB28: =AU28+AV28+AW28-AX28-AY28-AZ28-BA28 -> 3749 | BC28: =BB28/H28*100 -> 4.989486 | BD28: =AU28/$U28*100 -> 5198.2946 | BE28: =AV28/$U28*100 -> 18503.811 | BF28: =AW28/$U28*100 -> 4580.5007 | BG28: =AX28/$U28*100 -> 1424.7661 | BH28: =AY28/$U28*100 -> 3006.7216 | BI28: =AZ28/$U28*100 -> 11488.179 | BJ28: =BA28/$U28*100 -> 5745.4835 | BK28: =BD28+BE28+BF28-BG28-BH28-BI28-BJ28 -> 6617.4555 | BM28: 0.12940018 | BN28: =BM28*BO28 -> 49377.053 | BO28: 381584.12 | BP28: 607217.69 | BQ28: 14003.799 | BR28: 365589.49 | BS28: =BM28*BR28 -> 47307.344 | BT28: =BR28-BS28 -> 318282.14 | BU28: 227624.41 | BV28: 57737.627 | BW28: 32789.617 | BX28: 398334.52 | BY28: 118355.92 | BZ28: =BP28/$U28*100 -> 1071815.4 | CA28: =BQ28/$U28*100 -> 24718.462 | CB28: =BR28/$U28*100 -> 645311.33 | CC28: =BS28/$U28*100 -> 83503.4 | CD28: =BT28/$U28*100 -> 561807.93 | CE28: =BU28/$U28*100 -> 401785.64 | CF28: =BV28/$U28*100 -> 101914.16 | CG28: =BW28/$U28*100 -> 57877.789 | ... CI28: =BY28/$U28*100 -> 208913.06 | CK28: 81.267947 | CL28: 89.714659 | CM28: 84.104 | CN28: 5.52 | CO28: 71.67 | CP28: 53.892031 | CQ28: 19.907 | CR28: 18.05
A29: 35674 | B29: 37893 | C29: 7458 | D29: 38677.45 | E29: =H29-B29-C29-D29-F29+G29 -> -4125.9027 | F29: 65111.464 | G29: 62930.012 | H29: 82084 | I29: 57368 | J29: 11349 | K29: 57906.99 | L29: =O29-I29-J29-K29-M29+N29 -> 2464.4033 | M29: 102188.37 | N29: 91015.767 | O29: 140261 | P29: =B29/I29*100 -> 66.052503 | Q29: =C29/J29*100 -> 65.715041 | R29: =D29/K29*100 -> 66.792368 | S29: =F29/M29*100 -> 63.717096 | T29: =G29/N29*100 -> 69.141879 | U29: =H29/O29*100 -> 58.522326 | W29: 3268.7635 | X29: 5954.5442 | Z29: 73.214046 | AA29: 59 | AB29: 94 | AC29: 68 | AD29: =SUMPRODUCT($AA$1:$AC$1,AA29:AC29)/SUM($AA$1:$AC$1) -> 69.9 | AF29: 80.367979 | AG29: 80.367979 | AH29: =(Z29-0.8*AG29)/0.2 -> 44.598315 | AI29: =(Z29/Z25-1)*100 -> 2.2960075 | AJ29: =(AF29/AF25-1)*100*$AJ$1 -> 1.8889898 | AK29: =(AD29/AD25-1)*100*$AK$1 -> 0.26431718 | AL29: =AI29-AJ29-AK29 -> 0.1427005 | AN29: 7.5613333 | AO29: 7.6533333 | AP29: 10.74 | AQ29: =AP29-AN29 -> 3.1786667 | AR29: 2.7854 | AS29: 142.38333 | AU29: 3966 | AV29: 9631 | AW29: 2922 | AX29: 1011.2391 | AY29: 1319.0253 | AZ29: 8343.7356 | BA29: 3066 | BB29: =AU29+AV29+AW29-AX29-AY29-AZ29-BA29 -> 2779 | BC29: =BB29/H29*100 -> 3.3855563 | BD29: =AU29/$U29*100 -> 6776.9008 | BE29: =AV29/$U29*100 -> 16456.967 | BF29: =AW29/$U29*100 -> 4992.9663 | BG29: =AX29/$U29*100 -> 1727.9543 | BH29: =AY29/$U29*100 -> 2253.8839 | BI29: =AZ29/$U29*100 -> 14257.355 | BJ29: =BA29/$U29*100 -> 5239.0262 | BK29: =BD29+BE29+BF29-BG29-BH29-BI29-BJ29 -> 4748.6151 | BM29: 0.13642773 | BN29: =BM29*BO29 -> 54820.825 | BO29: 401830.53 | BP29: 639531.26 | BQ29: 15006.982 | BR29: 384748.84 | BS29: =BM29*BR29 -> 52490.409 | BT29: =BR29-BS29 -> 332258.43 | BU29: 239775.44 | BV29: 52021.1 | BW29: 36343.38 | BX29: 408796.89 | BY29: 142369.89 | BZ29: =BP29/$U29*100 -> 1092798.8 | CA29: =BQ29/$U29*100 -> 25643.174 | CB29: =BR29/$U29*100 -> 657439.41 | CC29: =BS29/$U29*100 -> 89692.963 | CD29: =BT29/$U29*100 -> 567746.45 | CE29: =BU29/$U29*100 -> 409716.18 | CF29: =BV29/$U29*100 -> 88891.032 | CG29: =BW29/$U29*100 -> 62101.735 | ... CI29: =BY29/$U29*100 -> 243274.49 | CK29: 83.227116 | CL29: 90.553315 | CM29: 83.891 | CN29: 5.53 | CO29: 71.837 | CP29: 52.462664 | CQ29: 19.783 | CR29: 18.51
A30: 35765 | B30: 37945 | C30: 11815 | D30: 38904.938 | E30: =H30-B30-C30-D30-F30+G30 -> -713.42923 | F30: 74644.569 | G30: 72788.078 | H30: 89808 | I30: 57852 | J30: 17819 | K30: 56021.225 | L30: =O30-I30-J30-K30-M30+N30 -> -5222.5519 | M30: 100582.68 | N30: 86245.349 | O30: 140807 | P30: =B30/I30*100 -> 65.589781 | Q30: =C30/J30*100 -> 66.305629 | R30: =D30/K30*100 -> 69.446782 | S30: =F30/M30*100 -> 74.212154 | T30: =G30/N30*100 -> 84.396527 | U30: =H30/O30*100 -> 63.78092 | W30: 3494.9271 | X30: 6320.6805 | Z30: 73.804113 | AA30: 59 | AB30: 94 | AC30: 68 | AD30: =SUMPRODUCT($AA$1:$AC$1,AA30:AC30)/SUM($AA$1:$AC$1) -> 69.9 | AF30: 80.827224 | AG30: 80.827224 | AH30: =(Z30-0.8*AG30)/0.2 -> 45.711668 | AI30: =(Z30/Z26-1)*100 -> 2.7133734 | AJ30: =(AF30/AF26-1)*100*$AJ$1 -> 1.9463702 | AK30: =(AD30/AD26-1)*100*$AK$1 -> 0.26431718 | AL30: =AI30-AJ30-AK30 -> 0.50268598 | AN30: 7.4626667 | AO30: 8.9 | AP30: 11.096667 | AQ30: =AP30-AN30 -> 3.634 | AR30: 3.4961 | AS30: 119.17 | AU30: 3437 | AV30: 10908 | AW30: 4558 | AX30: 1489.2044 | AY30: 2513.4311 | AZ30: 12031.365 | BA30: 6580 | BB30: =AU30+AV30+AW30-AX30-AY30-AZ30-BA30 -> -3711 | BC30: =BB30/H30*100 -> -4.1321486 | BD30: =AU30/$U30*100 -> 5388.7589 | BE30: =AV30/$U30*100 -> 17102.293 | BF30: =AW30/$U30*100 -> 7146.3378 | BG30: =AX30/$U30*100 -> 2334.8744 | BH30: =AY30/$U30*100 -> 3940.7256 | BI30: =AZ30/$U30*100 -> 18863.579 | BJ30: =BA30/$U30*100 -> 10316.565 | BK30: =BD30+BE30+BF30-BG30-BH30-BI30-BJ30 -> -5818.3545 | BM30: 0.13666521 | BN30: =BM30*BO30 -> 57607.164 | BO30: 421520.31 | BP30: 676934.97 | BQ30: 18019.65 | BR30: 401865.43 | BS30: =BM30*BR30 -> 54921.026 | BT30: =BR30-BS30 -> 346944.41 | BU30: 257049.89 | BV30: 52054.528 | BW30: 40318.264 | BX30: 435046.67 | BY30: 149515.51 | BZ30: =BP30/$U30*100 -> 1061344 | CA30: =BQ30/$U30*100 -> 28252.414 | CB30: =BR30/$U30*100 -> 630071.55 | CC30: =BS30/$U30*100 -> 86108.864 | CD30: =BT30/$U30*100 -> 543962.69 | CE30: =BU30/$U30*100 -> 403020.04 | CF30: =BV30/$U30*100 -> 81614.577 | CG30: =BW30/$U30*100 -> 63213.675 | ... CI30: =BY30/$U30*100 -> 234420.44 | CK30: 84.205155 | CL30: 91.37373 | CM30: 83.518 | CN30: 5.51 | CO30: 72.065 | CP30: 51.565524 | CQ30: 19.917 | CR30: 18.76
A31: 35855 | B31: 36231 | C31: 5440 | D31: 26509.833 | E31: =H31-B31-C31-D31-F31+G31 -> -80.0726 | F31: 77384.938 | G31: 67233.699 | H31: 78252 | I31: 52628 | J31: 8423 | K31: 35140.48 | L31: =O31-I31-J31-K31-M31+N31 -> 8698.2943 | M31: 96637.115 | N31: 76181.89 | O31: 125345 | P31: =B31/I31*100 -> 68.843581 | Q31: =C31/J31*100 -> 64.585065 | R31: =D31/K31*100 -> 75.439587 | S31: =F31/M31*100 -> 80.077865 | T31: =G31/N31*100 -> 88.254176 | U31: =H31/O31*100 -> 62.429295 | W31: 3348.2355 | X31: 6283.5318 | Z31: 76.014331 | AA31: 59 | AB31: 94 | AC31: 68 | AD31: =SUMPRODUCT($AA$1:$AC$1,AA31:AC31)/SUM($AA$1:$AC$1) -> 69.9 | AF31: 82.664781 | AG31: 82.664781 | AH31: =(Z31-0.8*AG31)/0.2 -> 49.41253 | AI31: =(Z31/Z27-1)*100 -> 4.3022307 | AJ31: =(AF31/AF27-1)*100*$AJ$1 -> 2.9476929 | AK31: =(AD31/AD27-1)*100*$AK$1 -> 0.26431718 | AL31: =AI31-AJ31-AK31 -> 1.0902206 | AN31: 9.9893333 | AO31: 9.4466667 | AP31: 12.543333 | AQ31: =AP31-AN31 -> 2.554 | AR31: 3.9848 | AS31: 110.46 | AU31: 3621 | AV31: 8108 | AW31: 2083 | AX31: 1310.4892 | AY31: 959.67762 | AZ31: 6164.8332 | BA31: 1174 | BB31: =AU31+AV31+AW31-AX31-AY31-AZ31-BA31 -> 4203 | BC31: =BB31/H31*100 -> 5.3711087 | BD31: =AU31/$U31*100 -> 5800.1616 | BE31: =AV31/$U31*100 -> 12987.492 | BF31: =AW31/$U31*100 -> 3336.5746 | BG31: =AX31/$U31*100 -> 2099.1574 | BH31: =AY31/$U31*100 -> 1537.2232 | BI31: =AZ31/$U31*100 -> 9874.9044 | BJ31: =BA31/$U31*100 -> 1880.5274 | BK31: =BD31+BE31+BF31-BG31-BH31-BI31-BJ31 -> 6732.4162 | BM31: 0.13108477 | BN31: =BM31*BO31 -> 55111.672 | BO31: 420427.74 | BP31: 642532.04 | BQ31: 17099.349 | BR31: 399558.72 | BS31: =BM31*BR31 -> 52376.062 | BT31: =BR31-BS31 -> 347182.66 | BU31: 225873.96 | BV31: 53144.713 | BW31: 31127.233 | BX31: 430778 | BY31: 127482.09 | BZ31: =BP31/$U31*100 -> 1029215.6 | CA31: =BQ31/$U31*100 -> 27389.944 | CB31: =BR31/$U31*100 -> 640018 | CC31: =BS31/$U31*100 -> 83896.609 | CD31: =BT31/$U31*100 -> 556121.39 | CE31: =BU31/$U31*100 -> 361807.65 | CF31: =BV31/$U31*100 -> 85127.844 | CG31: =BW31/$U31*100 -> 49859.978 | ... CI31: =BY31/$U31*100 -> 204202.36 | CK31: 86.125276 | CL31: 92.046631 | CM31: 82.678 | CN31: 5.52 | CO31: 72.277 | CP31: 49.142449 | CQ31: 15.93 | CR31: 14.1
A32: 35947 | B32: 32926 | C32: 6950 | D32: 22753.74 | E32: =H32-B32-C32-D32-F32+G32 -> 1764.7158 | F32: 75464.544 | G32: 62028.999 | H32: 77830 | I32: 48667 | J32: 10526 | K32: 30141.04 | L32: =O32-I32-J32-K32-M32+N32 -> 8891.4523 | M32: 97553.286 | N32: 71008.778 | O32: 124770 | P32: =B32/I32*100 -> 67.655701 | Q32: =C32/J32*100 -> 66.026981 | R32: =D32/K32*100 -> 75.490892 | S32: =F32/M32*100 -> 77.357254 | T32: =G32/N32*100 -> 87.353988 | U32: =H32/O32*100 -> 62.378777 | W32: 3326.0414 | X32: 5517.0761 | Z32: 77.070328 | AA32: 59 | AB32: 94 | AC32: 68 | AD32: =SUMPRODUCT($AA$1:$AC$1,AA32:AC32)/SUM($AA$1:$AC$1) -> 69.9 | AF32: 83.874289 | AG32: 83.874289 | AH32: =(Z32-0.8*AG32)/0.2 -> 49.854484 | AI32: =(Z32/Z28-1)*100 -> 5.7279222 | AJ32: =(AF32/AF28-1)*100*$AJ$1 -> 3.7510349 | AK32: =(AD32/AD28-1)*100*$AK$1 -> 0.086580087 | AL32: =AI32-AJ32-AK32 -> 1.8903072 | AN32: 10.065667 | AO32: 10.026667 | AP32: 13.513333 | AQ32: =AP32-AN32 -> 3.4476667 | AR32: 3.8539 | AS32: 114.02667 | AU32: 2585 | AV32: 8811 | AW32: 2654 | AX32: 835.55439 | AY32: 1836.474 | AZ32: 9355.9716 | BA32: 2405 | BB32: =AU32+AV32+AW32-AX32-AY32-AZ32-BA32 -> -383 | BC32: =BB32/H32*100 -> -0.49209816 | BD32: =AU32/$U32*100 -> 4144.0376 | BE32: =AV32/$U32*100 -> 14124.996 | BF32: =AW32/$U32*100 -> 4254.6522 | BG32: =AX32/$U32*100 -> 1339.485 | BH32: =AY32/$U32*100 -> 2944.0686 | BI32: =AZ32/$U32*100 -> 14998.645 | BJ32: =BA32/$U32*100 -> 3855.478 | BK32: =BD32+BE32+BF32-BG32-BH32-BI32-BJ32 -> -613.99088 | BM32: 0.12532295 | BN32: =BM32*BO32 -> 52702.113 | BO32: 420530.42 | BP32: 623665.25 | BQ32: 18149.365 | BR32: 400007.16 | BS32: =BM32*BR32 -> 50130.077 | BT32: =BR32-BS32 -> 349877.08 | BU32: 205508.73 | BV32: 49244.661 | BW32: 29758.358 | BX32: 422342.26 | BY32: 122319.97 | BZ32: =BP32/$U32*100 -> 999803.58 | CA32: =BQ32/$U32*100 -> 29095.416 | CB32: =BR32/$U32*100 -> 641255.21 | CC32: =BS32/$U32*100 -> 80363.995 | CD32: =BT32/$U32*100 -> 560891.21 | CE32: =BU32/$U32*100 -> 329452.96 | CF32: =BV32/$U32*100 -> 78944.575 | CG32: =BW32/$U32*100 -> 47705.902 | ... CI32: =BY32/$U32*100 -> 196092.29 | CK32: 86.478154 | CL32: 92.730958 | CM32: 82.234 | CN32: 5.5 | CO32: 72.498 | CP32: 48.160079 | CQ32: 14.653 | CR32: 13.31
A33: 36039 | B33: 33683 | C33: 7612 | D33: 19404.037 | E33: =H33-B33-C33-D33-F33+G33 -> 4357.7668 | F33: 80377.549 | G33: 63211.353 | H33: 82223 | I33: 50309 | J33: 11547 | K33: 25222.515 | L33: =O33-I33-J33-K33-M33+N33 -> 9567.6723 | M33: 99868.272 | N33: 70513.46 | O33: 126001 | P33: =B33/I33*100 -> 66.952235 | Q33: =C33/J33*100 -> 65.921884 | R33: =D33/K33*100 -> 76.931411 | S33: =F33/M33*100 -> 80.483568 | T33: =G33/N33*100 -> 89.644378 | U33: =H33/O33*100 -> 65.255831 | W33: 3325.7469 | X33: 5032.894 | Z33: 77.366528 | AA33: 59 | AB33: 94 | AC33: 68 | AD33: =SUMPRODUCT($AA$1:$AC$1,AA33:AC33)/SUM($AA$1:$AC$1) -> 69.9 | AF33: 84.468656 | AG33: 84.468656 | AH33: =(Z33-0.8*AG33)/0.2 -> 48.958016 | AI33: =(Z33/Z29-1)*100 -> 5.6717012 | AJ33: =(AF33/AF29-1)*100*$AJ$1 -> 4.0819014 | AK33: =(AD33/AD29-1)*100*$AK$1 -> 0 | AL33: =AI33-AJ33-AK33 -> 1.5897998 | AN33: 8.461 | AO33: 8.6466667 | AP33: 12.556667 | AQ33: =AP33-AN33 -> 4.0956667 | AR33: 4.0591 | AS33: 110.56667 | AU33: 3052 | AV33: 8004 | AW33: 3378 | AX33: 1057.4162 | AY33: 1422.0677 | AZ33: 6871.5161 | BA33: 3585 | BB33: =AU33+AV33+AW33-AX33-AY33-AZ33-BA33 -> 1498 | BC33: =BB33/H33*100 -> 1.8218747 | BD33: =AU33/$U33*100 -> 4676.9767 | BE33: =AV33/$U33*100 -> 12265.571 | BF33: =AW33/$U33*100 -> 5176.5489 | BG33: =AX33/$U33*100 -> 1620.4163 | BH33: =AY33/$U33*100 -> 2179.2194 | BI33: =AZ33/$U33*100 -> 10530.118 | BJ33: =BA33/$U33*100 -> 5493.7619 | BK33: =BD33+BE33+BF33-BG33-BH33-BI33-BJ33 -> 2295.5803 | BM33: 0.12150674 | BN33: =BM33*BO33 -> 51017.668 | BO33: 419875.2 | BP33: 610015.4 | BQ33: 18783.588 | BR33: 400185.34 | BS33: =BM33*BR33 -> 48625.217 | BT33: =BR33-BS33 -> 351560.12 | BU33: 191046.47 | BV33: 48426.414 | BW33: 23841.177 | BX33: 423051.24 | BY33: 114696.57 | BZ33: =BP33/$U33*100 -> 934805.96 | CA33: =BQ33/$U33*100 -> 28784.535 | CB33: =BR33/$U33*100 -> 613256.06 | CC33: =BS33/$U33*100 -> 74514.747 | CD33: =BT33/$U33*100 -> 538741.31 | CE33: =BU33/$U33*100 -> 292765.36 | CF33: =BV33/$U33*100 -> 74210.095 | CG33: =BW33/$U33*100 -> 36534.937 | ... CI33: =BY33/$U33*100 -> 175764.48 | CK33: 87.155225 | CL33: 93.465965 | CM33: 81.561 | CN33: 5.53 | CO33: 72.756 | CP33: 45.148292 | CQ33: 14.13 | CR33: 12.46
A34: 36130 | B34: 34224 | C34: 9111 | D34: 22388.847 | E34: =H34-B34-C34-D34-F34+G34 -> -3418.4686 | F34: 81415.211 | G34: 61927.589 | H34: 81793 | I34: 51757 | J34: 13798 | K34: 30832.059 | L34: =O34-I34-J34-K34-M34+N34 -> -4095.0652 | M34: 104276.15 | N34: 71505.144 | O34: 125063 | P34: =B34/I34*100 -> 66.124389 | Q34: =C34/J34*100 -> 66.031309 | R34: =D34/K34*100 -> 72.615477 | S34: =F34/M34*100 -> 78.076541 | T34: =G34/N34*100 -> 86.605783 | U34: =H34/O34*100 -> 65.401438 | W34: 3487.56 | X34: 4955.7102 | Z34: 77.770288 | AA34: 59 | AB34: 94 | AC34: 68 | AD34: =SUMPRODUCT($AA$1:$AC$1,AA34:AC34)/SUM($AA$1:$AC$1) -> 69.9 | AF34: 84.664628 | AG34: 84.664628 | AH34: =(Z34-0.8*AG34)/0.2 -> 50.192927 | AI34: =(Z34/Z30-1)*100 -> 5.3739208 | AJ34: =(AF34/AF30-1)*100*$AJ$1 -> 3.7981297 | AK34: =(AD34/AD30-1)*100*$AK$1 -> 0 | AL34: =AI34-AJ34-AK34 -> 1.575791 | AN34: 5.9446667 | AO34: 5.9333333 | AP34: 10.013333 | AQ34: =AP34-AN34 -> 4.0686667 | AR34: 3.8005 | AS34: 111.03 | AU34: 2934 | AV34: 8221 | AW34: 3259 | AX34: 1605.5403 | AY34: 2709.7806 | AZ34: 10454.679 | BA34: 9964 | BB34: =AU34+AV34+AW34-AX34-AY34-AZ34-BA34 -> -10320 | BC34: =BB34/H34*100 -> -12.617217 | BD34: =AU34/$U34*100 -> 4486.1399 | BE34: =AV34/$U34*100 -> 12570.06 | BF34: =AW34/$U34*100 -> 4983.0709 | BG34: =AX34/$U34*100 -> 2454.9006 | BH34: =AY34/$U34*100 -> 4143.3044 | BI34: =AZ34/$U34*100 -> 15985.396 | BJ34: =BA34/$U34*100 -> 15235.139 | BK34: =BD34+BE34+BF34-BG34-BH34-BI34-BJ34 -> -15779.47 | BM34: 0.12326917 | BN34: =BM34*BO34 -> 51014.259 | BO34: 413844.41 | BP34: 616319.13 | BQ34: 19160.615 | BR34: 394421.65 | BS34: =BM34*BR34 -> 48620.03 | BT34: =BR34-BS34 -> 345801.61 | BU34: 202736.86 | BV34: 48945.985 | BW34: 27461.932 | BX34: 433388.53 | BY34: 106522.68 | BZ34: =BP34/$U34*100 -> 942363.27 | CA34: =BQ34/$U34*100 -> 29296.933 | CB34: =BR34/$U34*100 -> 603077.94 | CC34: =BS34/$U34*100 -> 74340.92 | CD34: =BT34/$U34*100 -> 528737.02 | CE34: =BU34/$U34*100 -> 309988.39 | CF34: =BV34/$U34*100 -> 74839.311 | CG34: =BW34/$U34*100 -> 41989.799 | ... CI34: =BY34/$U34*100 -> 162875.14 | CK34: 87.976281 | CL34: 94.291183 | CM34: 81.249 | CN34: 4.86 | CO34: 72.988 | CP34: 43.818511 | CQ34: 12.84 | CR34: 11.21
